{
  "timestamp": "2025-08-18T15:18:56.643834",
  "environment": "production",
  "summary": {
    "total_checks": 13,
    "checks_passed": 6,
    "checks_failed": 7,
    "warnings": 7,
    "success_rate": 46.15,
    "ready_for_deployment": false
  },
  "critical_issues": [],
  "issues": [
    "Missing environment variables: DATABASE_URL, STRIPE_PUBLISHABLE_KEY, STRIPE_SECRET_KEY, STRIPE_WEBHOOK_SECRET, AWS_ACCESS_KEY_ID, AWS_SECRET_ACCESS_KEY, AWS_STORAGE_BUCKET_NAME",
    "Django config issue: DEBUG is True in production",
    "Django config issue: ALLOWED_HOSTS is not properly configured",
    "Django config issue: SECURE_SSL_REDIRECT should be True in production",
    "Django config issue: SESSION_COOKIE_SECURE should be True in production",
    "Django config issue: CSRF_COOKIE_SECURE should be True in production",
    "Test suite failed: ============================= test session starts =============================\nplatform win32 -- Python 3.13.5, pytest-8.4.1, pluggy-1.6.0\nbenchmark: 5.1.0 (defaults: timer=time.perf_counter disable_gc=False min_rounds=5 min_time=0.000005 max_time=1.0 calibration_precision=10 warmup=False warmup_iterations=100000)\ndjango: version: 5.2.5, settings: markethub.settings (from env)\nrootdir: C:\\Users\\Pardon\\MarketHub-Django-WebApp\nconfigfile: pytest.ini\nplugins: anyio-4.10.0, django-test-plus-2.2.2, Faker-20.1.0, benchmark-5.1.0, cov-4.1.0, django-4.8.0\ncollected 91 items / 1 error\n\n=================================== ERRORS ====================================\n________________ ERROR collecting tests/test_authentication.py ________________\nImportError while importing test module 'C:\\Users\\Pardon\\MarketHub-Django-WebApp\\tests\\test_authentication.py'.\nHint: make sure your test modules/packages have valid Python names.\nTraceback:\nC:\\Program Files\\Python313\\Lib\\importlib\\__init__.py:88: in import_module\n    return _bootstrap._gcd_import(name[level:], package, level)\n           ^^^^^^^^^^^^^^^^^^^^^^^^^^^^^^^^^^^^^^^^^^^^^^^^^^^^\ntests\\test_authentication.py:25: in <module>\n    from django_axes.helpers import get_client_ip_address\nE   ModuleNotFoundError: No module named 'django_axes'\n============================== warnings summary ===============================\ntests\\test_api.py:34\n  C:\\Users\\Pardon\\MarketHub-Django-WebApp\\tests\\test_api.py:34: PytestUnknownMarkWarning: Unknown pytest.mark.api - is this a typo?  You can register custom marks to avoid this warning - for details, see https://docs.pytest.org/en/stable/how-to/mark.html\n    @pytest.mark.api\n\ntests\\test_api.py:188\n  C:\\Users\\Pardon\\MarketHub-Django-WebApp\\tests\\test_api.py:188: PytestUnknownMarkWarning: Unknown pytest.mark.api - is this a typo?  You can register custom marks to avoid this warning - for details, see https://docs.pytest.org/en/stable/how-to/mark.html\n    @pytest.mark.api\n\ntests\\test_api.py:307\n  C:\\Users\\Pardon\\MarketHub-Django-WebApp\\tests\\test_api.py:307: PytestUnknownMarkWarning: Unknown pytest.mark.api - is this a typo?  You can register custom marks to avoid this warning - for details, see https://docs.pytest.org/en/stable/how-to/mark.html\n    @pytest.mark.api\n\ntests\\test_api.py:363\n  C:\\Users\\Pardon\\MarketHub-Django-WebApp\\tests\\test_api.py:363: PytestUnknownMarkWarning: Unknown pytest.mark.api - is this a typo?  You can register custom marks to avoid this warning - for details, see https://docs.pytest.org/en/stable/how-to/mark.html\n    @pytest.mark.api\n\ntests\\test_api.py:453\n  C:\\Users\\Pardon\\MarketHub-Django-WebApp\\tests\\test_api.py:453: PytestUnknownMarkWarning: Unknown pytest.mark.api - is this a typo?  You can register custom marks to avoid this warning - for details, see https://docs.pytest.org/en/stable/how-to/mark.html\n    @pytest.mark.api\n\ntests\\test_api.py:499\n  C:\\Users\\Pardon\\MarketHub-Django-WebApp\\tests\\test_api.py:499: PytestUnknownMarkWarning: Unknown pytest.mark.api - is this a typo?  You can register custom marks to avoid this warning - for details, see https://docs.pytest.org/en/stable/how-to/mark.html\n    @pytest.mark.api\n\ntests\\test_api.py:570\n  C:\\Users\\Pardon\\MarketHub-Django-WebApp\\tests\\test_api.py:570: PytestUnknownMarkWarning: Unknown pytest.mark.api - is this a typo?  You can register custom marks to avoid this warning - for details, see https://docs.pytest.org/en/stable/how-to/mark.html\n    @pytest.mark.api\n\ntests\\test_api.py:630\n  C:\\Users\\Pardon\\MarketHub-Django-WebApp\\tests\\test_api.py:630: PytestUnknownMarkWarning: Unknown pytest.mark.api - is this a typo?  You can register custom marks to avoid this warning - for details, see https://docs.pytest.org/en/stable/how-to/mark.html\n    @pytest.mark.api\n\ntests\\test_api.py:661\n  C:\\Users\\Pardon\\MarketHub-Django-WebApp\\tests\\test_api.py:661: PytestUnknownMarkWarning: Unknown pytest.mark.api - is this a typo?  You can register custom marks to avoid this warning - for details, see https://docs.pytest.org/en/stable/how-to/mark.html\n    @pytest.mark.api\n\ntests\\test_api.py:737\n  C:\\Users\\Pardon\\MarketHub-Django-WebApp\\tests\\test_api.py:737: PytestUnknownMarkWarning: Unknown pytest.mark.api - is this a typo?  You can register custom marks to avoid this warning - for details, see https://docs.pytest.org/en/stable/how-to/mark.html\n    @pytest.mark.api\n\n-- Docs: https://docs.pytest.org/en/stable/how-to/capture-warnings.html\n=========================== short test summary info ===========================\nERROR tests/test_authentication.py\n!!!!!!!!!!!!!!!!!!!!!!!!!! stopping after 1 failures !!!!!!!!!!!!!!!!!!!!!!!!!!\n======================== 10 warnings, 1 error in 3.08s ========================\n "
  ],
  "recommendations": [
    "Fix code quality issues before deployment",
    "Consider using connection pooling for better performance",
    "Configure Sentry for production error tracking",
    "Verify SSL certificates are properly configured"
  ],
  "deployment_readiness": "NOT READY"
}